Workbook
Name סכומים: #REF!

Sheet Prop ID
A1: Prop ID | B1: client | C1: Address | D1: Key
A2: 3 | B2: Lisac | D2: 14 | F2: *
A3: 5 | B3: Jacobson | D3: 20 | F3: *
A4: 6 | B4: Wurtman | D4: 25 | F4: *
A5: 17 | B5: sommer | D5: 31
A6: 22 | B6: Fischer | D6: 1 | F6: *
A7: 23 | B7: Frank
A8: 95 | B8: Greenstone | D8: 44 | F8: *
A9: 120 | B9: Schindler | D9: 26 | F9: *
A10: 162 | B10: Aboudi | D10: * | F10: *
A11: 183 | B11: Netanel | D11: 13 | F11: *
A12: 210
A13: 225 | B13: Kaplan | D13: 6
A14: 257 | B14: Pollack/Rotenberg | D14: 27,28,29 | F14: *
A15: 258 | B15: Mayerfeld | D15: 15 | F15: *
A16: 265 | B16: Hainey | D16: 4 | F16: *
A17: 273 | B17: Licht | D17: 18 | F17: *
A18: 277 | B18: Hockstein | D18: 10 | F18: *
A19: 555 | B19: Rosenberg | D19: *
A20: 535 | B20: Fruchter
A21: 618 | B21: Silver + master | D21: 7 | F21: *
A22: 619 | B22: silver | D22: 8 | F22: *
A23: 707 | B23: Cohen | D23: 47 | F23: *
A24: 801 | B24: silver | D24: 9 | F24: *
A25: 280 | B25: edson | D25: 2 | F25: *
B26: turner | D26: 38
A27: 77 | B27: charles | D27: *
A28: Sale/ rental
B29: meizner | D29: 37
B30: lee hod | D30: 40
B31: Epstien | D31: 42
B32: Frank | D32: 45

Sheet Dashboard
A1: Property | B1: Expenses | C1: Inflow | D1: Balance | E1: tikun cash | F1: Client Name | G1: דוח אחרון | H1: מספר לקוח | J1: ת.ז סנדי 317179455 | M1: אם אי פי מקרקעין ג.ר בע"מ
A2: 3 | B2: =SUM('03 EX'!F:F) -> 182931.32 | C2: =SUM('03 EX'!G:G) -> 183057.31 | D2: =C2-B2 -> 125.99 | F2: ליסאק | G2: 44602 | H2: 3 | J2: טלפון סנדי: 054-4910603
A3: 4 | B3: =SUM('04 EX'!F:F) -> 1632 | C3: =SUM('04 EX'!G:G) -> 1435 | D3: =C3-B3 -> -197 | F3: פנטנוביץ | H3: 4
A4: 5 | B4: =SUM('05 ex'!F:F) -> 325834.34 | C4: =SUM('05 ex'!G:G) -> 326338.33 | D4: =C4-B4 -> 503.99 | G4: 11/06/20525 | H4: 5
A5: 8 | B5: =SUM('08 ex'!F:F) -> 30505.04 | C5: =SUM('08 ex'!G:G) -> 31087.2 | D5: =C5-B5 -> 582.16 | G5: 45652 | H5: 8
A6: 12 | B6: =SUM('12 ex'!F:F) -> 46626.64 | C6: =SUM('12 ex'!G:G) -> 46626.64 | D6: =C6-B6 -> 0 | G6: 45496 | H6: 12
A7: 13 | B7: =SUM('13'!F:F) -> 103617.5 | C7: =SUM('13'!G:G) -> 106999.8 | D7: =C7-B7 -> 3382.3 | G7: 45543 | H7: 13
A8: 9 | B8: =SUM('09 ex'!F:F) -> 2253.34 | C8: =SUM('09 ex'!G:G) -> 2253.34 | D8: =C8-B8 -> 0 | H8: 9
A9: 17 | B9: =SUM('17'!F:F) -> 72341.84 | C9: =SUM('17'!G:G) -> 72341.95 | D9: =C9-B9 -> 0.11 | G9: 45898 | H9: 17
A10: 25 | B10: =SUM('25'!F:F) -> 27851.2 | C10: =SUM('25'!G:G) -> 27792 | D10: =C10-B10 -> -59.2 | G10: 45714 | H10: 25
A11: 30 | B11: =SUM('30'!F:F) -> 40000 | C11: =SUM('30'!G:G) -> 40000 | D11: =C11-B11 -> 0 | G11: 45508 | H11: 30
A12: 36 | B12: =SUM('36'!F:F) -> 12975.29 | C12: =SUM('36'!G:G) -> 19227.43 | D12: =C12-B12 -> 6252.14 | G12: 45898 | H12: 36
A13: 84 | B13: =SUM('84'!F:F) -> 88428.08 | C13: =SUM('84'!G:G) -> 147000 | D13: =C13-B13 -> 58571.92 | G13: 45774 | H13: 84 | I13: *
A14: 106 | B14: =SUM('106'!F:F) -> 11000 | C14: =SUM('106'!G:G) -> 11000 | D14: =C14-B14 -> 0 | G14: 45552 | H14: 106
A15: 111 | B15: =SUM('111'!F:F) -> 20807 | C15: =SUM('111'!G:G) -> 23815 | D15: =C15-B15 -> 3008 | G15: 45898 | H15: 111
A16: 120 | B16: =SUM('120 EX'!F:F) -> 90636.41 | C16: =SUM('120 EX'!G:G) -> 90636.25 | D16: =C16-B16 -> -0.16 | G16: 45076 | H16: 120
A17: 131 | B17: =SUM('131'!F:F) -> 33608.06 | C17: =SUM('131'!G:G) -> 33000 | D17: =C17-B17 -> -608.06 | G17: 45672 | H17: 131
A18: 149 | B18: =SUM('149'!F:F) -> 11895.96 | C18: =SUM('149'!G:G) -> 17025.6 | D18: =C18-B18 -> 5129.64 | H18: 149
A19: 301 | B19: =SUM('301'!F:F) -> 5097.58 | C19: =SUM('301'!G:G) -> 7943.86 | D19: =C19-B19 -> 2846.28 | H19: 301
A20: 1210 | B20: =SUM('1210'!F:F) -> 3567.05 | C20: =SUM('1210'!G:G) -> 4400 | D20: =C20-B20 -> 832.95 | H20: 1210
A21: 1301 | B21: =SUM('1301'!F:F) -> 5762 | C21: =SUM('1301'!G:G) -> 5762 | D21: =C21-B21 -> 0 | H21: 1301
A22: 183 | B22: =SUM('183 ex'!F:F) -> 89118.633 | C22: =SUM('183 ex'!G:G) -> 92935.4 | D22: =C22-B22 -> 3816.7665 | E22: 1017.6 | G22: 45774 | H22: 183 | I22: ***
A23: 210 | B23: =SUM('210'!F:F) -> 480.1 | C23: =SUM('210'!G:G) -> 480.1 | D23: =C23-B23 -> 0 | H23: 210
A24: 257 | B24: =SUM('257 Ex'!F:F) -> 889845.93 | C24: =SUM('257 Ex'!G:G) -> 894321.61 | D24: =C24-B24 -> 4475.68 | G24: 45708 | H24: 257
A25: 273 | B25: =SUM('273 EX'!F:F) -> 404803.26 | C25: =SUM('273 EX'!G:G) -> 403303.81 | D25: =C25-B25 -> -1499.4535 | E25: 800 | G25: 45774 | H25: 273
A26: H003/H111 | B26: =SUM('H111'!F:F) -> 93056.015 | C26: =SUM('H111'!G:G) -> 93056.02 | D26: =C26-B26 -> 0.005 | G26: 44783 | H26: H003/H111
A27: 277 | B27: =SUM('277 EX'!F:F) -> 635594.65 | C27: =SUM('277 EX'!G:G) -> 637025.28 | D27: =C27-B27 -> 1430.63 | E27: 939.5 | G27: 45693 | H27: 277
A28: 535 | B28: =SUM('535'!F:F) -> 34518.345 | C28: =SUM('535'!G:G) -> 34518.2 | D28: =C28-B28 -> -0.145 | G28: 45252 | H28: 535
A29: 707 | B29: =SUM('707 EX'!F:F) -> 469529.13 | C29: =SUM('707 EX'!G:G) -> 469529.13 | D29: =C29-B29 -> 0 | G29: 45643 | H29: 707
A30: 567 | B30: =SUM('567'!F:F) -> 0 | C30: =SUM('567'!G:G) -> 0 | D30: =C30-B30 -> 0 | H30: 567
A31: 618/619/801 | B31: =SUM('801-618- 619'!F:F) -> 49319.46 | C31: =SUM('801-618- 619'!G:G) -> 50706.4 | D31: =C31-B31 -> 1386.94 | G31: 44950 | H31: 618/619/801
A32: C15 | B32: =SUM('C15'!F:F) -> 59679.17 | C32: =SUM('C15'!G:G) -> 58421.54 | D32: =C32-B32 -> -1257.63 | G32: 45564 | H32: C15
A33: c19 | B33: =SUM('c19'!F:F) -> 374137.09 | C33: =SUM('c19'!G:G) -> 378722 | D33: =C33-B33 -> 4584.915 | G33: 45898 | H33: C19 | M33: 516497815
A34: c31 | B34: =SUM('c31'!F:F) -> 169590.66 | C34: =SUM('c31'!G:G) -> 181381.89 | D34: =C34-B34 -> 11791.23 | G34: 45690 | H34: C31
A35: c4 | B35: =SUM('c4 EX'!F:F) -> 311534.22 | C35: =SUM('c4 EX'!G:G) -> 314684 | D35: =C35-B35 -> 3149.7752 | G35: 45894 | H35: C4
A36: C50 | B36: =SUM('C50'!F:F) -> 80582.885 | C36: =SUM('C50'!G:G) -> 80582.89 | D36: =C36-B36 -> 0.005 | G36: 45167 | H36: C50
A37: C6 | B37: =SUM('06 ex'!F:F) -> 356402.04 | C37: =SUM('06 ex'!G:G) -> 353399 | D37: =C37-B37 -> -3003.04 | G37: 25/0/2025 | H37: C6
A38: C8 | B38: =SUM('C8'!F:F) -> 3914.27 | C38: =SUM('C8'!G:G) -> 4189 | D38: =C38-B38 -> 274.73 | H38: C8
A39: N160 | B39: =SUM('N160'!F:F) -> 48443.58 | C39: =SUM('N160'!G:G) -> 46694.56 | D39: =C39-B39 -> -1749.02 | H39: N160
A40: p14 | B40: =SUM('p14'!F:F) -> 104891.46 | C40: =SUM('p14'!G:G) -> 104319.79 | D40: =C40-B40 -> -571.67 | G40: 45574 | H40: P14 | I40: 2500 keep (29/01 goes back zucker)
...

Sheet Buffer
A1: Prop ID | B1: Date | C1: Type | D1: Amount | E1: Inflow | F1: MIP | G1: Method | H1: Reconciled | I1: Company | J1: reciept | K1: Returned | L1: Balance | M1: Total Amount | N1: Total Inflow
A2: Buffer | B2: 42322 | C2: עמלות בנק | D2: 10 | L2: =N2-M2 -> -3524.85 | M2: =SUM(D$19:$D723) -> 77361.65 | N2: =SUM(E$19:$E723) -> 73836.8
A3: Buffer | B3: 42323 | C3: עמלת בנק | D3: 10 | L3: =N3-M3 -> -3524.85 | M3: =SUM(D$19:$D723) -> 77361.65 | N3: =SUM(E$19:$E723) -> 73836.8
A4: Buffer | B4: 42324 | C4: עמלות בנק | D4: 13.2 | L4: =N4-M4 -> -3524.85 | M4: =SUM(D$19:$D723) -> 77361.65 | N4: =SUM(E$19:$E723) -> 73836.8
A5: Buffer | B5: 42325 | C5: דמי כרטיס אשראי | D5: 13.9 | L5: =N5-M5 -> -3524.85 | M5: =SUM(D$19:$D723) -> 77361.65 | N5: =SUM(E$19:$E723) -> 73836.8
A6: Buffer | B6: 42326 | C6: דמי כרטיס אשראי | D6: 13.9 | L6: =N6-M6 -> -3524.85 | M6: =SUM(D$19:$D723) -> 77361.65 | N6: =SUM(E$19:$E723) -> 73836.8
A7: Buffer | B7: 42327 | C7: חומרי בניין דוד מלכה - לא ידוע | D7: 19 | L7: =N7-M7 -> -3524.85 | M7: =SUM(D$19:$D723) -> 77361.65 | N7: =SUM(E$19:$E723) -> 73836.8
A8: Buffer | B8: 42328 | C8: עמלת בנק | D8: 34.65 | L8: =N8-M8 -> -3524.85 | M8: =SUM(D$19:$D723) -> 77361.65 | N8: =SUM(E$19:$E723) -> 73836.8
A9: Buffer | B9: 42329 | C9: תיקון מים בוריס - סילבר | D9: 52.8 | L9: =N9-M9 -> -3524.85 | M9: =SUM(D$19:$D723) -> 77361.65 | N9: =SUM(E$19:$E723) -> 73836.8
A10: Buffer | B10: 42330 | C10: מים ג'קובסון | D10: 150 | L10: =N10-M10 -> -3524.85 | M10: =SUM(D$19:$D723) -> 77361.65 | N10: =SUM(E$19:$E723) -> 73836.8
A11: Buffer | B11: 42331 | C11: חשמל דייר 277 | D11: 152 | L11: =N11-M11 -> -3524.85 | M11: =SUM(D$19:$D723) -> 77361.65 | N11: =SUM(E$19:$E723) -> 73836.8
A12: Buffer | B12: 42332 | C12: חשמל ג'קובסון | D12: 200 | L12: =N12-M12 -> -3524.85 | M12: =SUM(D$19:$D723) -> 77361.65 | N12: =SUM(E$19:$E723) -> 73836.8
A13: Buffer | B13: 42333 | C13: העברה לסנדי פועלים | D13: 1500 | L13: =N13-M13 -> -3524.85 | M13: =SUM(D$19:$D723) -> 77361.65 | N13: =SUM(E$19:$E723) -> 73836.8
A14: Buffer | B14: 42334 | C14: כסף לבאפר | E14: 3000 | L14: =N14-M14 -> -3524.85 | M14: =SUM(D$19:$D723) -> 77361.65 | N14: =SUM(E$19:$E723) -> 73836.8
A15: Buffer | B15: 42335 | C15: עמלת תיווך גרי | E15: 1500 | L15: =N15-M15 -> -3524.85 | M15: =SUM(D$19:$D723) -> 77361.65 | N15: =SUM(E$19:$E723) -> 73836.8
A16: Buffer | B16: 42336 | C16: תיקון פולק | E16: 250 | L16: =N16-M16 -> -3524.85 | M16: =SUM(D$19:$D723) -> 77361.65 | N16: =SUM(E$19:$E723) -> 73836.8
A17: Buffer | B17: 42337 | C17: הנחה כרטיס אשראי | E17: 5.1 | L17: =N17-M17 -> -3524.85 | M17: =SUM(D$19:$D723) -> 77361.65 | N17: =SUM(E$19:$E723) -> 73836.8
A18: Buffer | B18: 42338 | C18: צבעי 183 | E18: 400 | L18: =N18-M18 -> -3524.85 | M18: =SUM(D$19:$D723) -> 77361.65 | N18: =SUM(E$19:$E723) -> 73836.8
A19: Buffer | B19: 42339 | C19: car insurance | D19: 95 | H19: y | L19: =N19-M19 -> -95 | M19: =SUM($D$19:D19) -> 95 | N19: =SUM($E$19:E19) -> 0
A20: Buffer | B20: 42390 | C20: Kvish 6 | D20: 252.64 | G20: cc | L20: =N20-M20 -> -347.64 | M20: =SUM($D$19:D20) -> 347.64 | N20: =SUM($E$19:E20) -> 0
A21: Buffer | B21: 42401 | C21: bank fee | D21: 10 | G21: t | H21: y | L21: =N21-M21 -> -357.64 | M21: =SUM($D$19:D21) -> 357.64 | N21: =SUM($E$19:E21) -> 0
A22: Buffer | B22: 42417 | C22: credit fee | D22: 1.52 | G22: cc | L22: =N22-M22 -> -359.16 | M22: =SUM($D$19:D22) -> 359.16 | N22: =SUM($E$19:E22) -> 0
A23: Buffer | B23: 42417 | C23: efax | D23: 52.05 | G23: cc | H23: y | L23: =N23-M23 -> -411.21 | M23: =SUM($D$19:D23) -> 411.21 | N23: =SUM($E$19:E23) -> 0
A24: Buffer | B24: 42425 | C24: fees | D24: 1.82 | G24: cc | L24: =N24-M24 -> -413.03 | M24: =SUM($D$19:D24) -> 413.03 | N24: =SUM($E$19:E24) -> 0
A25: Buffer | B25: 42425 | C25: google storage | D25: 7.77 | G25: cc | H25: y | L25: =N25-M25 -> -420.8 | M25: =SUM($D$19:D25) -> 420.8 | N25: =SUM($E$19:E25) -> 0
A26: Buffer | B26: 42425 | C26: credot fee | D26: 13.9 | G26: cc | H26: y | L26: =N26-M26 -> -434.7 | M26: =SUM($D$19:D26) -> 434.7 | N26: =SUM($E$19:E26) -> 0
A27: Buffer | B27: 42430 | C27: bank fee | D27: 10 | G27: t | H27: y | L27: =N27-M27 -> -444.7 | M27: =SUM($D$19:D27) -> 444.7 | N27: =SUM($E$19:E27) -> 0
A28: Buffer | B28: 42436 | C28: clothes | D28: 57 | G28: cc | H28: y | L28: =N28-M28 -> -501.7 | M28: =SUM($D$19:D28) -> 501.7 | N28: =SUM($E$19:E28) -> 0
A29: Buffer | B29: 42436 | C29: clothes | D29: 189.9 | G29: cc | H29: y | L29: =N29-M29 -> -691.6 | M29: =SUM($D$19:D29) -> 691.6 | N29: =SUM($E$19:E29) -> 0
A30: Buffer | B30: 42436 | C30: clothes | D30: 259 | G30: cc | H30: y | L30: =N30-M30 -> -950.6 | M30: =SUM($D$19:D30) -> 950.6 | N30: =SUM($E$19:E30) -> 0
A31: Buffer | B31: 42437 | C31: efax | E31: 98.13 | G31: cc | H31: y | L31: =N31-M31 -> -852.47 | M31: =SUM($D$19:D31) -> 950.6 | N31: =SUM($E$19:E31) -> 98.13
A32: Buffer | B32: 42438 | C32: payment hockstien | E32: 4713 | G32: t | H32: y | L32: =N32-M32 -> 3860.53 | M32: =SUM($D$19:D32) -> 950.6 | N32: =SUM($E$19:E32) -> 4811.13
A33: Buffer | B33: 42439 | C33: payment hockstien | D33: 4713 | G33: t | H33: y | L33: =N33-M33 -> -852.47 | M33: =SUM($D$19:D33) -> 5663.6 | N33: =SUM($E$19:E33) -> 4811.13
A34: Buffer | B34: 42443 | C34: Sandi payment | E34: 10000 | L34: =N34-M34 -> 9147.53 | M34: =SUM($D$19:D34) -> 5663.6 | N34: =SUM($E$19:E34) -> 14811.13
A35: Buffer | B35: 42454 | C35: foreign excahge | D35: 1.78 | G35: cc | H35: y | L35: =N35-M35 -> 9145.75 | M35: =SUM($D$19:D35) -> 5665.38 | N35: =SUM($E$19:E35) -> 14811.13
A36: Buffer | B36: 42454 | C36: google storage | D36: 7.63 | G36: cc | H36: y | L36: =N36-M36 -> 9138.12 | M36: =SUM($D$19:D36) -> 5673.01 | N36: =SUM($E$19:E36) -> 14811.13
A37: Buffer | B37: 42455 | C37: credit fee | D37: 13.9 | G37: cc | H37: y | L37: =N37-M37 -> 9124.22 | M37: =SUM($D$19:D37) -> 5686.91 | N37: =SUM($E$19:E37) -> 14811.13
A38: Buffer | B38: 42461 | C38: bank fee | D38: 3.3 | G38: t | H38: y | L38: =N38-M38 -> 9120.92 | M38: =SUM($D$19:D38) -> 5690.21 | N38: =SUM($E$19:E38) -> 14811.13
A39: Buffer | B39: 42461 | C39: bank fee | D39: 10 | G39: t | L39: =N39-M39 -> 9110.92 | M39: =SUM($D$19:D39) -> 5700.21 | N39: =SUM($E$19:E39) -> 14811.13
A40: Buffer | B40: 42465 | C40: transfer to Leumi | D40: 10000 | H40: y | L40: =N40-M40 -> -889.08 | M40: =SUM($D$19:D40) -> 15700.21 | N40: =SUM($E$19:E40) -> 14811.13
...

Sheet expenses
A1: Prop ID | B1: Date | C1: Type | D1: Amount | E1: Balance | F1: Method | G1: Company | H1: reciept | I1: return | J1: reported
A14: 618 | C14: Starting balance | E14: 5000
A15: 618 | B15: 42327 | C15: renovation | D15: -1680 | G15: שש תיקונים
A16: 618 | B16: 42328 | C16: key/mail lock | D16: -19
A17: 618 | B17: 42334 | C17: chip for building | D17: -25
A18: 618 | B18: 40876 | C18: cleaner | D18: -200
A19: 619 | B19: 42327 | C19: renovation | D19: -3120
A20: 619 | B20: 42328 | C20: cleaning supplies | D20: -13.5
A21: 619 | B21: 42328 | C21: Cleaner | D21: -400
A22: 619 | B22: 42328 | C22: cleaning supplies | D22: -84.7
A23: 619 | B23: 42335 | C23: key | D23: -19
A24: 619 | B24: 42337 | C24: Electrican | D24: -450
A25: 619 | B25: 42348 | C25: Finders fee | D25: -2047.5 | F25: transfer | G25: MIP | H25: 223
A26: 618 | B26: 42348 | C26: Finders fee | D26: -468 | F26: transfer | G26: MIP | H26: 223
A27: 618 | B27: 42348 | C27: management fee Oct | D27: -333.45 | F27: transfer | G27: MIP | H27: 223
A28: 619 | B28: 42348 | C28: management fee Oct | D28: -315.9 | F28: transfer | G28: MIP | H28: 223
A29: 801 | B29: 42348 | C29: management fee Oct- Dec | D29: -684.45 | F29: transfer | G29: MIP | H29: 223
A30: 618 | B30: 42348 | C30: management fee Dec | D30: -351 | F30: transfer | G30: MIP | H30: 223
A31: 619 | B31: 42348 | C31: management fee Dec | D31: -306.54 | F31: transfer | G31: MIP | H31: 223
A32: 618 | B32: 42353 | C32: fees | E32: 4507
A33: 618 | B33: 42353 | C33: prepaid expenses | E33: 3911.2 | F33: transfer | H33: 12
A34: 619 | C34: a/c | D34: -2800

Sheet bills
A1: Prop ID | B1: Date | C1: Type | D1: Amount | E1: Balance | F1: Method | G1: Company | H1: reciept
A2: 257 | B2: 42296 | C2: Pool July August sept | D2: 5499 | F2: Josaiah | G2: Maman Eyal | H2: 366 | I2: salt barmod and pump
A3: 257 | B3: 42354 | C3: Pool Oct, Nov | D3: 1404 | F3: Josaiah | G3: Maman Eyal
A4: 257 | B4: 42354 | C4: Mazger electic gate and driveway phone | D4: 4563 | F4: Josaiah | G4: Tal Matechet
A5: 257 | C5: glass work | D5: 18206 | F5: Josaiah | G5: נחמני מוטי | I5: glass work for pool bathroom kids bathrom, fence around jacuzzi and mirror
A6: 257 | B6: 42367 | C6: cleaning | D6: 1111.5 | F6: Josaiah | G6: ניקיון אחר
A7: 257 | B7: 42380 | C7: pool dec- pool pump | D7: 2106 | F7: Josaiah | G7: Maman Eyal

Sheet OldBuffer
A1: Prop ID | B1: Date | C1: Date | D1: Type | E1: Amount | F1: Inflow | G1: Method | H1: Reconciled | I1: Company | J1: reciept | K1: Returned
B2: 42339 | C2: 42339 | D2: car insuance | E2: 95 | H2: y
B3: 42390 | C3: 42390 | D3: Kvish 6 | E3: 252.64 | G3: credit
B4: 42401 | C4: 42401 | D4: bank fee | E4: 10 | G4: bank fee | H4: y
B5: 42417 | C5: 42417 | D5: credit fee | E5: 1.52 | G5: credit
B6: 42417 | C6: 42417 | D6: efax | E6: 52.05 | G6: credit | H6: y
B7: 42425 | C7: 42425 | D7: fees | E7: 1.82 | G7: credit
B8: 42425 | C8: 42425 | D8: google storage | E8: 7.77 | G8: credit | H8: y
B9: 42425 | C9: 42425 | D9: credot fee | E9: 13.9 | G9: credit | H9: y
B10: 42430 | C10: 42430 | D10: bank fee | E10: 10 | G10: bank | H10: y
B11: 42436 | C11: 42436 | D11: clothes | E11: 189.9 | G11: credit | H11: y
B12: 42436 | C12: 42436 | D12: clothes | E12: 57 | G12: credit | H12: y
B13: 42436 | C13: 42436 | D13: clothes | E13: 259 | G13: credit | H13: y
B14: 42437 | C14: 42437 | D14: efax | F14: 98.13 | G14: credit | H14: y
B15: 42438 | C15: 42438 | D15: payment hockstien | F15: 4713 | G15: transfer | H15: y
B16: 42439 | C16: 42439 | D16: payment hockstien | E16: 4713 | G16: transfer | H16: y
B17: 42443 | C17: 42443 | D17: Sandi payment | F17: 10000
B18: 42454 | C18: 42454 | D18: foreign excahge | E18: 1.78 | G18: credit fee | H18: y
B19: 42454 | C19: 42454 | D19: google storage | E19: 7.63 | G19: credit | H19: y
B20: 42455 | C20: 42455 | D20: credit fee | E20: 13.9 | G20: credit | H20: y
B21: 42461 | C21: 42461 | D21: bank fee | E21: 3.3 | G21: bank fee | H21: y
B22: 42461 | C22: 42461 | D22: bank fee | E22: 10
B23: 42465 | C23: 42465 | D23: transfer to Leumi | E23: 10000 | H23: y
B24: 42486 | C24: 42486 | D24: credit card fee | E24: 13.9 | H24: y
B25: 42486 | C25: 42486 | D25: google storage | E25: 7.7 | H25: y
B26: 42491 | C26: 42491 | D26: bank fee | E26: 4.95 | H26: y
B27: 42492 | C27: 42492 | D27: bank fee | E27: 10 | H27: y
B28: 42508 | C28: 42508 | D28: home center? | E28: 90 | H28: y
B29: 42516 | C29: 42516 | D29: currency transfer fee | E29: 1.78 | H29: y
B30: 42516 | C30: 42516 | D30: credit card fee | E30: 13.9 | H30: y
B31: 42516 | C31: 42516 | D31: google storage | E31: 7.63 | H31: y
B32: 42522 | C32: 42522 | D32: Start | E32: 0 | F32: 2392
B33: 42522 | C33: 42522 | D33: bank fee | E33: 10 | H33: y
B34: 42523 | C34: 42523 | D34: Adjustment | E34: 18.21
B35: 42532 | C35: 42532 | D35: bekek | E35: 38.9 | H35: y
B36: 42533 | C36: 42533 | D36: took out cash of 1300 to cover cash expenses of 479, 120,180, | E36: 1300
B37: 42536 | C37: 42536 | D37: cash for clients | E37: 200 | H37: y
B38: 42546 | C38: 42546 | D38: credit fee | E38: 13.9 | H38: y
B39: 42546 | C39: 42546 | D39: google storage | E39: 7.94 | H39: y
B40: 42548 | C40: 42548 | D40: bank fee | E40: 24 | H40: y
...

Sheet 03 EX
A1: Prop ID | B1: Date | C1: Section | D1: Notes | E1: Type | F1: Amount | G1: Inflow | H1: He/She paid | I1: Method | J1: Reconciled | K1: Company | L1: Reciept | M1: Rental income | N1: Reported | O1: Report sent | P1: Balance | Q1: Total Amount | R1: Total Inflow
A2: 03 | B2: 42471 | C2: Pre paid expenses | G2: 1200 | J2: y | N2: Y | P2: =R2-Q2 -> 1200 | Q2: =SUM($F$2:F2) -> 0 | R2: =SUM($G$2:G2) -> 1200
A3: 03 | B3: 42473 | C3: locksmith | F3: 395 | I3: check | J3: y | K3: Chaim Manuilim | L3: 8307 | N3: Y | P3: =R3-Q3 -> 805 | Q3: =SUM($F$2:F3) -> 395 | R3: =SUM($G$2:G3) -> 1200
A4: 03 | B4: 42495 | C4: Arnona | F4: 140.3 | I4: credit | J4: y | K4: Moatza | L4: 1213584 | N4: Y | P4: =R4-Q4 -> 664.7 | Q4: =SUM($F$2:F4) -> 535.3 | R4: =SUM($G$2:G4) -> 1200
A5: 03 | B5: 42523 | C5: cleaning | F5: 702 | I5: transfer | J5: y | L5: 283 | N5: Y | P5: =R5-Q5 -> -37.3 | Q5: =SUM($F$2:F5) -> 1237.3 | R5: =SUM($G$2:G5) -> 1200
A6: 03 | B6: 42551 | C6: laundry | F6: 195 | I6: credit | J6: y | K6: סל כביסה | L6: 291 | N6: Y | P6: =R6-Q6 -> -232.3 | Q6: =SUM($F$2:F6) -> 1432.3 | R6: =SUM($G$2:G6) -> 1200
A7: 03 | B7: 42565 | C7: Pre paid expenses | G7: 8283.1 | I7: transfer | J7: y | N7: Y | P7: =R7-Q7 -> 8050.8 | Q7: =SUM($F$2:F7) -> 1432.3 | R7: =SUM($G$2:G7) -> 9483.1
A8: 03 | B8: 42569 | C8: Gardener - Graham | F8: 3140 | I8: transfer | J8: y | K8: Graham Eskin | L8: 80 | N8: Y | P8: =R8-Q8 -> 4910.8 | Q8: =SUM($F$2:F8) -> 4572.3 | R8: =SUM($G$2:G8) -> 9483.1
A9: 03 | B9: 42578 | C9: Exterminator | F9: 400 | I9: transfer | J9: y | K9: עדי מזרחי | L9: 1839 | N9: Y | P9: =R9-Q9 -> 4510.8 | Q9: =SUM($F$2:F9) -> 4972.3 | R9: =SUM($G$2:G9) -> 9483.1
A10: 03 | B10: 42584 | C10: pre paid expenses | G10: 6696 | I10: cash | N10: Y | P10: =R10-Q10 -> 11206.8 | Q10: =SUM($F$2:F10) -> 4972.3 | R10: =SUM($G$2:G10) -> 16179.1
A11: 03 | B11: 42619 | C11: cleaning | F11: 3510 | I11: transfer | J11: y | K11: ניקיון אחר | L11: 337 | N11: Y | P11: =R11-Q11 -> 7696.8 | Q11: =SUM($F$2:F11) -> 8482.3 | R11: =SUM($G$2:G11) -> 16179.1
A12: 03 | B12: 42635 | C12: gardener !/2 may, june, july and august plus parts | F12: 1738 | I12: transfer | J12: y | K12: Graham Eskin | L12: 92 | N12: Y | P12: =R12-Q12 -> 5958.8 | Q12: =SUM($F$2:F12) -> 10220.3 | R12: =SUM($G$2:G12) -> 16179.1
A13: 03 | B13: 42643 | C13: water 14-6-16 till 15-8-16 | H13: 758.85 | J13: y | K13: tagid mayanot | L13: 1178078 | N13: Y | P13: =R13-Q13 -> 5958.8 | Q13: =SUM($F$2:F13) -> 10220.3 | R13: =SUM($G$2:G13) -> 16179.1
A14: 03 | B14: 42648 | C14: cleaning 30-9-16 | F14: 702 | I14: transfer | J14: y | K14: ניקיון אחר | L14: 364 | N14: Y | P14: =R14-Q14 -> 5256.8 | Q14: =SUM($F$2:F14) -> 10922.3 | R14: =SUM($G$2:G14) -> 16179.1
A15: 03 | B15: 42675 | C15: Cleaning supplies | F15: 38.5 | I15: credit | J15: y | K15: super habaron | L15: 87930 | N15: Y | P15: =R15-Q15 -> 5218.3 | Q15: =SUM($F$2:F15) -> 10960.8 | R15: =SUM($G$2:G15) -> 16179.1
A16: 03 | B16: 42687 | C16: cleaning 2-11-16 | F16: 702 | I16: transfer | J16: y | K16: ניקיון אחר | L16: 414 | N16: Y | P16: =R16-Q16 -> 4516.3 | Q16: =SUM($F$2:F16) -> 11662.8 | R16: =SUM($G$2:G16) -> 16179.1
A17: 03 | B17: 42688 | C17: Pre paid expenses | G17: 3056 | I17: cash | J17: y | L17: 65 | N17: Y | P17: =R17-Q17 -> 7572.3 | Q17: =SUM($F$2:F17) -> 11662.8 | R17: =SUM($G$2:G17) -> 19235.1
A18: 03 | B18: 42725 | C18: Cleaning supplies | F18: 12.9 | I18: credit | J18: y | K18: sefa habaron | L18: 94320 | N18: Y | P18: =R18-Q18 -> 7559.4 | Q18: =SUM($F$2:F18) -> 11675.7 | R18: =SUM($G$2:G18) -> 19235.1
A19: 03 | B19: 42726 | C19: Pre paid expenses | G19: 6130.02 | I19: tranfer | J19: y | K19: Sandi Ryker | L19: 295 | N19: Y | P19: =R19-Q19 -> 13689.42 | Q19: =SUM($F$2:F19) -> 11675.7 | R19: =SUM($G$2:G19) -> 25365.12
A20: 03 | B20: 42736 | C20: Sandi payment | F20: 7120 | I20: transfer | J20: y | L20: 295/296 | N20: Y | P20: =R20-Q20 -> 6569.42 | Q20: =SUM($F$2:F20) -> 18795.7 | R20: =SUM($G$2:G20) -> 25365.12
A21: 03 | B21: 42737 | C21: management fee- | F21: 3510 | I21: transfer | J21: y | K21: MIP | L21: 302 | N21: Y | P21: =R21-Q21 -> 3059.42 | Q21: =SUM($F$2:F21) -> 22305.7 | R21: =SUM($G$2:G21) -> 25365.12
A22: 03 | B22: 42738 | C22: roof | F22: 585 | I22: transfer | J22: y | K22: michelle | N22: Y | P22: =R22-Q22 -> 2474.42 | Q22: =SUM($F$2:F22) -> 22890.7 | R22: =SUM($G$2:G22) -> 25365.12
A23: 03 | B23: 42738 | C23: shower head | F23: 160 | I23: cc | K23: ronis | N23: Y | P23: =R23-Q23 -> 2314.42 | Q23: =SUM($F$2:F23) -> 23050.7 | R23: =SUM($G$2:G23) -> 25365.12
A24: 03 | B24: 42799 | C24: gardener sept- jan | F24: 3978 | I24: transfer | J24: y | K24: Graham Eskin | L24: 94 | N24: Y | P24: =R24-Q24 -> -1663.58 | Q24: =SUM($F$2:F24) -> 27028.7 | R24: =SUM($G$2:G24) -> 25365.12
A25: 03 | B25: 42801 | C25: cleaning | F25: 702 | I25: transfer | J25: y | K25: Nikayon acher | L25: 503 | N25: Y | P25: =R25-Q25 -> -2365.58 | Q25: =SUM($F$2:F25) -> 27730.7 | R25: =SUM($G$2:G25) -> 25365.12
A26: 03 | B26: 42821 | C26: Pre paid expenses | G26: 4000 | I26: 5000396 | J26: y | K26: MIP | L26: 83 | N26: Y | P26: =R26-Q26 -> 1634.42 | Q26: =SUM($F$2:F26) -> 27730.7 | R26: =SUM($G$2:G26) -> 29365.12
A27: 03 | B27: 42825 | C27: window | F27: 40 | I27: cash | J27: y | K27: ben | L27: no | N27: Y | P27: =R27-Q27 -> 1594.42 | Q27: =SUM($F$2:F27) -> 27770.7 | R27: =SUM($G$2:G27) -> 29365.12
A28: 03 | B28: 42859 | C28: cleaning 31-3 | F28: 702 | I28: transfer | J28: y | K28: Nikayon acher | L28: 528 | N28: Y | P28: =R28-Q28 -> 892.42 | Q28: =SUM($F$2:F28) -> 28472.7 | R28: =SUM($G$2:G28) -> 29365.12
A29: 03 | B29: 42859 | C29: cleaning 25-4-17 | F29: 702 | I29: transfer | J29: y | K29: Nikayon acher | L29: 531 | N29: Y | P29: =R29-Q29 -> 190.42 | Q29: =SUM($F$2:F29) -> 29174.7 | R29: =SUM($G$2:G29) -> 29365.12
A30: 03 | B30: 42872 | C30: pre paid expenses | G30: 712 | J30: y | N30: Y | P30: =R30-Q30 -> 902.42 | Q30: =SUM($F$2:F30) -> 29174.7 | R30: =SUM($G$2:G30) -> 30077.12
A31: 03 | B31: 42874 | C31: Plumber | F31: 351 | J31: y | L31: 70 | N31: Y | P31: =R31-Q31 -> 551.42 | Q31: =SUM($F$2:F31) -> 29525.7 | R31: =SUM($G$2:G31) -> 30077.12
A32: 03 | B32: 42877 | C32: shower head | F32: 269 | I32: cc | J32: y | K32: Ronis | L32: RC179000470 | N32: Y | P32: =R32-Q32 -> 282.42 | Q32: =SUM($F$2:F32) -> 29794.7 | R32: =SUM($G$2:G32) -> 30077.12
A33: 03 | B33: 42877 | C33: Pre paid expenses | G33: 10552.89 | I33: tramsfer | J33: y | K33: MIP | L33: 89 | N33: Y | P33: =R33-Q33 -> 10835.31 | Q33: =SUM($F$2:F33) -> 29794.7 | R33: =SUM($G$2:G33) -> 40630.01
A34: 03 | B34: 42878 | C34: management fee- | F34: 3510 | I34: transfer | J34: y | K34: MIP | L34: 320 | N34: Y | P34: =R34-Q34 -> 7325.31 | Q34: =SUM($F$2:F34) -> 33304.7 | R34: =SUM($G$2:G34) -> 40630.01
A35: 03 | B35: 42878 | C35: Gardener | F35: 4092 | I35: transfer | J35: y | K35: Graham | L35: 97 | N35: Y | P35: =R35-Q35 -> 3233.31 | Q35: =SUM($F$2:F35) -> 37396.7 | R35: =SUM($G$2:G35) -> 40630.01
A36: 03 | B36: 42885 | C36: water 03-04 | H36: 117.92 | N36: Y | P36: =R36-Q36 -> 3233.31 | Q36: =SUM($F$2:F36) -> 37396.7 | R36: =SUM($G$2:G36) -> 40630.01
A37: 03 | B37: 42908 | C37: milk | F37: 6.8 | I37: cc | J37: y | K37: super shefa habaron | N37: Y | P37: =R37-Q37 -> 3226.51 | Q37: =SUM($F$2:F37) -> 37403.5 | R37: =SUM($G$2:G37) -> 40630.01
A38: 03 | B38: 42928 | C38: Cleaning 22-6-17 | F38: 702 | I38: transfer | J38: y | K38: nikayon acher | L38: 571 | N38: Y | P38: =R38-Q38 -> 2524.51 | Q38: =SUM($F$2:F38) -> 38105.5 | R38: =SUM($G$2:G38) -> 40630.01
A39: 03 | B39: 42933 | C39: wall repairs | F39: 750 | I39: transfer | J39: y | K39: chaim dasa | N39: Y | P39: =R39-Q39 -> 1774.51 | Q39: =SUM($F$2:F39) -> 38855.5 | R39: =SUM($G$2:G39) -> 40630.01
A40: 03 | B40: 42934 | C40: shower head | F40: 269 | I40: cc | J40: y | K40: Ronis | L40: Rc179000690 | N40: Y | P40: =R40-Q40 -> 1505.51 | Q40: =SUM($F$2:F40) -> 39124.5 | R40: =SUM($G$2:G40) -> 40630.01
...

Sheet 04 EX
A1: Prop ID | B1: Date | C1: Section | D1: Notes | E1: Type | F1: Amount | G1: Inflow | H1: He/She paid | I1: Method | J1: Reconciled | K1: Company | L1: Reciept | M1: Rental income | N1: Reported | O1: Report sent | P1: Balance | Q1: Total Amount | R1: Total Inflow
A2: 04 | B2: 43864 | C2: Keys | F2: 135 | I2: cc | J2: y | K2: חיים מנעולים | L2: 9843 | N2: Y | P2: =R2-Q2 -> -135 | Q2: =SUBTOTAL(9,$F$2:F2) -> 135 | R2: =SUBTOTAL(9,$G$2:G2) -> 0
A3: 04 | B3: 43871 | C3: Paid in cash | G3: 135 | I3: מזומן | J3: y | N3: Y | P3: =R3-Q3 -> 0 | Q3: =SUBTOTAL(9,$F$2:F3) -> 135 | R3: =SUBTOTAL(9,$G$2:G3) -> 135
A4: 04 | B4: 43873 | C4: Electrician | F4: 234 | I4: t | J4: y | K4: איתי דרור | L4: 642 | N4: Y | P4: =R4-Q4 -> -234 | Q4: =SUBTOTAL(9,$F$2:F4) -> 369 | R4: =SUBTOTAL(9,$G$2:G4) -> 135
A5: 04 | B5: 43880 | C5: pre paid | G5: 700 | I5: שק | J5: y | N5: Y | P5: =R5-Q5 -> 466 | Q5: =SUBTOTAL(9,$F$2:F5) -> 369 | R5: =SUBTOTAL(9,$G$2:G5) -> 835
A6: 04 | B6: 43886 | F6: 550 | I6: t | J6: y | K6: עוזי אגסי | N6: Y | O6: 44153 | P6: =R6-Q6 -> -84 | Q6: =SUBTOTAL(9,$F$2:F6) -> 919 | R6: =SUBTOTAL(9,$G$2:G6) -> 835
A7: 04 | B7: 44188 | C7: pre paid | G7: 600 | I7: t | J7: y | P7: =R7-Q7 -> 516 | Q7: =SUBTOTAL(9,$F$2:F7) -> 919 | R7: =SUBTOTAL(9,$G$2:G7) -> 1435
A8: 04 | B8: 44265 | C8: Rent deposit | M8: 4300 | P8: =R8-Q8 -> 516 | Q8: =SUBTOTAL(9,$F$2:F8) -> 919 | R8: =SUBTOTAL(9,$G$2:G8) -> 1435
A9: 04 | B9: 44449 | C9: Rent deposit | M9: 4300 | P9: =R9-Q9 -> 516 | Q9: =SUBTOTAL(9,$F$2:F9) -> 919 | R9: =SUBTOTAL(9,$G$2:G9) -> 1435
A10: 04 | B10: 44510 | C10: Rent deposit | M10: 4300 | P10: =R10-Q10 -> 516 | Q10: =SUBTOTAL(9,$F$2:F10) -> 919 | R10: =SUBTOTAL(9,$G$2:G10) -> 1435
A11: 04 | B11: 44540 | C11: Rent deposit | M11: 4300 | P11: =R11-Q11 -> 516 | Q11: =SUBTOTAL(9,$F$2:F11) -> 919 | R11: =SUBTOTAL(9,$G$2:G11) -> 1435
A12: 04 | B12: 44571 | C12: Rent deposit | M12: 4300 | P12: =R12-Q12 -> 516 | Q12: =SUBTOTAL(9,$F$2:F12) -> 919 | R12: =SUBTOTAL(9,$G$2:G12) -> 1435
A13: 04 | B13: 44630 | C13: Rent deposit | M13: 4691 | P13: =R13-Q13 -> 516 | Q13: =SUBTOTAL(9,$F$2:F13) -> 919 | R13: =SUBTOTAL(9,$G$2:G13) -> 1435
A14: 04 | B14: 44661 | C14: Rent deposit | M14: 4691 | P14: =R14-Q14 -> 516 | Q14: =SUBTOTAL(9,$F$2:F14) -> 919 | R14: =SUBTOTAL(9,$G$2:G14) -> 1435
A15: 04 | B15: 44691 | C15: Rent deposit | M15: 4691 | P15: =R15-Q15 -> 516 | Q15: =SUBTOTAL(9,$F$2:F15) -> 919 | R15: =SUBTOTAL(9,$G$2:G15) -> 1435
A16: 04 | B16: 44722 | C16: Rent deposit | M16: 4691 | P16: =R16-Q16 -> 516 | Q16: =SUBTOTAL(9,$F$2:F16) -> 919 | R16: =SUBTOTAL(9,$G$2:G16) -> 1435
A17: 04 | B17: 44752 | C17: Rent deposit | M17: 4691 | P17: =R17-Q17 -> 516 | Q17: =SUBTOTAL(9,$F$2:F17) -> 919 | R17: =SUBTOTAL(9,$G$2:G17) -> 1435
A18: 04 | B18: 44778 | C18: Repair of air conditioner leak | D18: תיקון נזילת מזגן | F18: 363 | P18: =R18-Q18 -> 153 | Q18: =SUBTOTAL(9,$F$2:F18) -> 1282 | R18: =SUBTOTAL(9,$G$2:G18) -> 1435
A19: 04 | B19: 44784 | C19: Rent deposit | M19: 4691 | P19: =R19-Q19 -> 153 | Q19: =SUBTOTAL(9,$F$2:F19) -> 1282 | R19: =SUBTOTAL(9,$G$2:G19) -> 1435
A20: 04 | B20: 44816 | C20: Rent deposit | M20: 4691 | P20: =R20-Q20 -> 153 | Q20: =SUBTOTAL(9,$F$2:F20) -> 1282 | R20: =SUBTOTAL(9,$G$2:G20) -> 1435
A21: 04 | B21: 44878 | C21: Rent deposit | M21: 4691 | P21: =R21-Q21 -> 153 | Q21: =SUBTOTAL(9,$F$2:F21) -> 1282 | R21: =SUBTOTAL(9,$G$2:G21) -> 1435
A22: 04 | B22: 44906 | C22: Rent deposit | M22: 4691 | P22: =R22-Q22 -> 153 | Q22: =SUBTOTAL(9,$F$2:F22) -> 1282 | R22: =SUBTOTAL(9,$G$2:G22) -> 1435
A23: 04 | B23: 44923 | C23: Air conditioner repair | F23: 350 | K23: שולמן מזגנים | P23: =R23-Q23 -> -197 | Q23: =SUBTOTAL(9,$F$2:F23) -> 1632 | R23: =SUBTOTAL(9,$G$2:G23) -> 1435
A24: 04 | B24: 44938 | C24: Rent deposit | M24: 4691 | P24: =R24-Q24 -> -197 | Q24: =SUBTOTAL(9,$F$2:F24) -> 1632 | R24: =SUBTOTAL(9,$G$2:G24) -> 1435
P25: =R25-Q25 -> -197 | Q25: =SUBTOTAL(9,$F$2:F25) -> 1632 | R25: =SUBTOTAL(9,$G$2:G25) -> 1435

Sheet 08 ex
A1: Prop ID | B1: Date | C1: Section | D1: Notes | E1: Type | F1: Amount | G1: Inflow | H1: He/She paid | I1: Method | J1: Reconciled | K1: Company | L1: Reciept | M1: Rental income | N1: Reported | O1: Report sent | P1: Balance | Q1: Total Amount | R1: Total Inflow
A2: 08 | B2: 43830 | C2: pre paid | G2: 1000 | I2: t | J2: y | N2: Y | P2: =R2-Q2 -> 1000 | Q2: =SUBTOTAL(9,$F$2:F2) -> 0 | R2: =SUBTOTAL(9,$G$2:G2) -> 1000
A3: 08 | B3: 43846 | C3: חשמל | F3: 27.64 | N3: Y | P3: =R3-Q3 -> 972.36 | Q3: =SUBTOTAL(9,$F$2:F3) -> 27.64 | R3: =SUBTOTAL(9,$G$2:G3) -> 1000
A4: 08 | B4: 43846 | C4: ארנונה | F4: 563.2 | N4: Y | P4: =R4-Q4 -> 409.16 | Q4: =SUBTOTAL(9,$F$2:F4) -> 590.84 | R4: =SUBTOTAL(9,$G$2:G4) -> 1000
A5: 08 | B5: 43865 | C5: שילם בטעות לפה את הניהול | G5: 8424 | N5: Y | P5: =R5-Q5 -> 8833.16 | Q5: =SUBTOTAL(9,$F$2:F5) -> 590.84 | R5: =SUBTOTAL(9,$G$2:G5) -> 9424
A6: 08 | B6: 43867 | C6: העברתי לסנדי | F6: 8424 | N6: Y | P6: =R6-Q6 -> 409.16 | Q6: =SUBTOTAL(9,$F$2:F6) -> 9014.84 | R6: =SUBTOTAL(9,$G$2:G6) -> 9424
A7: 08 | B7: 43937 | C7: שכירות | M7: 7200 | N7: Y | P7: =R7-Q7 -> 409.16 | Q7: =SUBTOTAL(9,$F$2:F7) -> 9014.84 | R7: =SUBTOTAL(9,$G$2:G7) -> 9424
A8: 08 | B8: 43949 | C8: אבי קודיש חשמלאי | F8: 200 | I8: t | J8: y | N8: Y | P8: =R8-Q8 -> 209.16 | Q8: =SUBTOTAL(9,$F$2:F8) -> 9214.84 | R8: =SUBTOTAL(9,$G$2:G8) -> 9424
A9: 08 | B9: 43962 | C9: ניהול בטעות העביר לפה | G9: 2527.2 | I9: t | J9: y | N9: Y | P9: =R9-Q9 -> 2736.36 | Q9: =SUBTOTAL(9,$F$2:F9) -> 9214.84 | R9: =SUBTOTAL(9,$G$2:G9) -> 11951.2
A10: 08 | B10: 43965 | C10: ניהול העברתי לסנדי | F10: 2527.2 | I10: t | J10: y | N10: Y | P10: =R10-Q10 -> 209.16 | Q10: =SUBTOTAL(9,$F$2:F10) -> 11742.04 | R10: =SUBTOTAL(9,$G$2:G10) -> 11951.2
A11: 08 | B11: 44020 | C11: התקנת מערכת פילטרים | F11: 1521 | I11: t | J11: y | K11: אשר ברינבאום | L11: 755 | N11: Y | O11: 44022 | P11: =R11-Q11 -> -1311.84 | Q11: =SUBTOTAL(9,$F$2:F11) -> 13263.04 | R11: =SUBTOTAL(9,$G$2:G11) -> 11951.2
A12: 08 | B12: 44031 | C12: שכירות | M12: 7200 | N12: Y | P12: =R12-Q12 -> -1311.84 | Q12: =SUBTOTAL(9,$F$2:F12) -> 13263.04 | R12: =SUBTOTAL(9,$G$2:G12) -> 11951.2
A13: 08 | B13: 44059 | C13: שכירות | M13: 7200 | N13: Y | P13: =R13-Q13 -> -1311.84 | Q13: =SUBTOTAL(9,$F$2:F13) -> 13263.04 | R13: =SUBTOTAL(9,$G$2:G13) -> 11951.2
A14: 08 | B14: 44088 | C14: pre paid | G14: 2500 | I14: t | J14: y | N14: Y | P14: =R14-Q14 -> 1188.16 | Q14: =SUBTOTAL(9,$F$2:F14) -> 13263.04 | R14: =SUBTOTAL(9,$G$2:G14) -> 14451.2
A15: 08 | B15: 44123 | C15: שכירות | M15: 7200 | N15: Y | P15: =R15-Q15 -> 1188.16 | Q15: =SUBTOTAL(9,$F$2:F15) -> 13263.04 | R15: =SUBTOTAL(9,$G$2:G15) -> 14451.2
A16: 08 | B16: 44123 | C16: שכירות | M16: 7200 | N16: Y | P16: =R16-Q16 -> 1188.16 | Q16: =SUBTOTAL(9,$F$2:F16) -> 13263.04 | R16: =SUBTOTAL(9,$G$2:G16) -> 14451.2
A17: 08 | B17: 44151 | C17: שכירות | M17: 7200 | N17: Y | P17: =R17-Q17 -> 1188.16 | Q17: =SUBTOTAL(9,$F$2:F17) -> 13263.04 | R17: =SUBTOTAL(9,$G$2:G17) -> 14451.2
A18: 08 | B18: 44180 | C18: שכירות | M18: 7200 | N18: Y | P18: =R18-Q18 -> 1188.16 | Q18: =SUBTOTAL(9,$F$2:F18) -> 13263.04 | R18: =SUBTOTAL(9,$G$2:G18) -> 14451.2
A19: 08 | B19: 44193 | C19: Management Sandi | D19: ניהול בטעות העביר לפה | G19: 7581.6 | I19: t | J19: y | N19: Y | P19: =R19-Q19 -> 8769.76 | Q19: =SUBTOTAL(9,$F$2:F19) -> 13263.04 | R19: =SUBTOTAL(9,$G$2:G19) -> 22032.8
A20: 08 | B20: 44194 | C20: Management Sandi | D20: ניהול העברתי לסנדי | F20: 7581.6 | I20: t | J20: y | N20: Y | P20: =R20-Q20 -> 1188.16 | Q20: =SUBTOTAL(9,$F$2:F20) -> 20844.64 | R20: =SUBTOTAL(9,$G$2:G20) -> 22032.8
A21: 08 | B21: 44214 | C21: Deposit of rent | M21: 7700 | N21: Y | P21: =R21-Q21 -> 1188.16 | Q21: =SUBTOTAL(9,$F$2:F21) -> 20844.64 | R21: =SUBTOTAL(9,$G$2:G21) -> 22032.8
A22: 08 | B22: 44242 | C22: Deposit of rent | M22: 7700 | N22: Y | P22: =R22-Q22 -> 1188.16 | Q22: =SUBTOTAL(9,$F$2:F22) -> 20844.64 | R22: =SUBTOTAL(9,$G$2:G22) -> 22032.8
A23: 08 | B23: 44273 | C23: Deposit of rent | M23: 7700 | N23: Y | P23: =R23-Q23 -> 1188.16 | Q23: =SUBTOTAL(9,$F$2:F23) -> 20844.64 | R23: =SUBTOTAL(9,$G$2:G23) -> 22032.8
A24: 08 | B24: 44306 | C24: Deposit of rent | M24: 7700 | N24: Y | P24: =R24-Q24 -> 1188.16 | Q24: =SUBTOTAL(9,$F$2:F24) -> 20844.64 | R24: =SUBTOTAL(9,$G$2:G24) -> 22032.8
A25: 08 | B25: 44337 | C25: Deposit of rent | M25: 7700 | N25: Y | P25: =R25-Q25 -> 1188.16 | Q25: =SUBTOTAL(9,$F$2:F25) -> 20844.64 | R25: =SUBTOTAL(9,$G$2:G25) -> 22032.8
A26: 08 | B26: 44364 | C26: Deposit of rent | M26: 7700 | N26: Y | P26: =R26-Q26 -> 1188.16 | Q26: =SUBTOTAL(9,$F$2:F26) -> 20844.64 | R26: =SUBTOTAL(9,$G$2:G26) -> 22032.8
A27: 08 | B27: 44374 | C27: Management Sandi | D27: בטעות העביר לפה | G27: 5054.4 | I27: t | J27: y | N27: Y | P27: =R27-Q27 -> 6242.56 | Q27: =SUBTOTAL(9,$F$2:F27) -> 20844.64 | R27: =SUBTOTAL(9,$G$2:G27) -> 27087.2
A28: 08 | B28: 44375 | C28: Management Sandi | D28: העברתי לסנדי | F28: 5054.4 | I28: t | J28: y | N28: Y | P28: =R28-Q28 -> 1188.16 | Q28: =SUBTOTAL(9,$F$2:F28) -> 25899.04 | R28: =SUBTOTAL(9,$G$2:G28) -> 27087.2
A29: 08 | B29: 44396 | C29: Deposit of rent | M29: 7700 | N29: Y | P29: =R29-Q29 -> 1188.16 | Q29: =SUBTOTAL(9,$F$2:F29) -> 25899.04 | R29: =SUBTOTAL(9,$G$2:G29) -> 27087.2
A30: 08 | B30: 44431 | C30: Deposit of rent | M30: 7700 | N30: Y | P30: =R30-Q30 -> 1188.16 | Q30: =SUBTOTAL(9,$F$2:F30) -> 25899.04 | R30: =SUBTOTAL(9,$G$2:G30) -> 27087.2
A31: 08 | B31: 44458 | C31: Deposit of rent | M31: 7700 | N31: Y | P31: =R31-Q31 -> 1188.16 | Q31: =SUBTOTAL(9,$F$2:F31) -> 25899.04 | R31: =SUBTOTAL(9,$G$2:G31) -> 27087.2
A32: 08 | B32: 44553 | C32: Deposit of rent | M32: 7700 | N32: Y | P32: =R32-Q32 -> 1188.16 | Q32: =SUBTOTAL(9,$F$2:F32) -> 25899.04 | R32: =SUBTOTAL(9,$G$2:G32) -> 27087.2
A33: 08 | B33: 44704 | C33: Deposit of rent | M33: 8700 | N33: Y | P33: =R33-Q33 -> 1188.16 | Q33: =SUBTOTAL(9,$F$2:F33) -> 25899.04 | R33: =SUBTOTAL(9,$G$2:G33) -> 27087.2
A34: 08 | B34: 44732 | C34: Deposit of rent | M34: 7700 | N34: Y | P34: =R34-Q34 -> 1188.16 | Q34: =SUBTOTAL(9,$F$2:F34) -> 25899.04 | R34: =SUBTOTAL(9,$G$2:G34) -> 27087.2
A35: 08 | B35: 44788 | C35: Deposit of rent | M35: 7700 | N35: Y | P35: =R35-Q35 -> 1188.16 | Q35: =SUBTOTAL(9,$F$2:F35) -> 25899.04 | R35: =SUBTOTAL(9,$G$2:G35) -> 27087.2
A36: 08 | B36: 44824 | C36: Deposit of rent | M36: 7700 | N36: Y | P36: =R36-Q36 -> 1188.16 | Q36: =SUBTOTAL(9,$F$2:F36) -> 25899.04 | R36: =SUBTOTAL(9,$G$2:G36) -> 27087.2
A37: 08 | B37: 44854 | C37: Deposit of rent | M37: 7700 | N37: Y | P37: =R37-Q37 -> 1188.16 | Q37: =SUBTOTAL(9,$F$2:F37) -> 25899.04 | R37: =SUBTOTAL(9,$G$2:G37) -> 27087.2
A38: 08 | B38: 44881 | C38: Deposit of rent | M38: 7700 | N38: Y | P38: =R38-Q38 -> 1188.16 | Q38: =SUBTOTAL(9,$F$2:F38) -> 25899.04 | R38: =SUBTOTAL(9,$G$2:G38) -> 27087.2
A39: 08 | B39: 44943 | C39: Deposit of rent | M39: 7700 | N39: Y | P39: =R39-Q39 -> 1188.16 | Q39: =SUBTOTAL(9,$F$2:F39) -> 25899.04 | R39: =SUBTOTAL(9,$G$2:G39) -> 27087.2
A40: 08 | B40: 44977 | C40: Deposit of rent | M40: 7700 | N40: Y | P40: =R40-Q40 -> 1188.16 | Q40: =SUBTOTAL(9,$F$2:F40) -> 25899.04 | R40: =SUBTOTAL(9,$G$2:G40) -> 27087.2
...

Sheet 05 ex
A1: Prop ID | B1: Date | C1: Section | D1: Notes | E1: Type | F1: Amount | G1: Inflow | H1: He/She paid | I1: Method | J1: Reconciled | K1: Company | L1: Reciept | M1: Rental income | N1: Reported | O1: Report sent | P1: Balance | Q1: Total Amount | R1: Total Inflow
A2: 05 | B2: 42514 | C2: electric | G2: 200 | I2: cash | J2: y | N2: Y | P2: =R2-Q2 -> 200 | Q2: =SUBTOTAL(9,$F$2:F2) -> 0 | R2: =SUBTOTAL(9,$G$2:G2) -> 200
A3: 05 | B3: 42738 | C3: keys | F3: 15 | I3: cc | J3: y | K3: chaim | L3: 8319 | N3: Y | P3: =R3-Q3 -> 185 | Q3: =SUBTOTAL(9,$F$2:F3) -> 15 | R3: =SUBTOTAL(9,$G$2:G3) -> 200
A4: 05 | B4: 42826 | C4: prepaid expenses | G4: 1068 | J4: y | K4: MIP | L4: 81 | N4: Y | P4: =R4-Q4 -> 1253 | Q4: =SUBTOTAL(9,$F$2:F4) -> 15 | R4: =SUBTOTAL(9,$G$2:G4) -> 1268
A5: 05 | B5: 42859 | C5: exterminator | F5: 450 | I5: transfer | J5: y | K5: עדי מזרחי | L5: 2115 | N5: Y | P5: =R5-Q5 -> 803 | Q5: =SUBTOTAL(9,$F$2:F5) -> 465 | R5: =SUBTOTAL(9,$G$2:G5) -> 1268
A6: 05 | B6: 42900 | C6: zack friend | F6: 45 | I6: transfer | J6: y | K6: zack | L6: no | N6: Y | P6: =R6-Q6 -> 758 | Q6: =SUBTOTAL(9,$F$2:F6) -> 510 | R6: =SUBTOTAL(9,$G$2:G6) -> 1268
A7: 05 | B7: 42901 | C7: keys | F7: 24 | I7: cc | J7: y | K7: chaim | L7: 7865 | N7: Y | P7: =R7-Q7 -> 734 | Q7: =SUBTOTAL(9,$F$2:F7) -> 534 | R7: =SUBTOTAL(9,$G$2:G7) -> 1268
A8: 05 | B8: 42901 | C8: Plumber | F8: 1368 | J8: y | L8: 57 | N8: Y | P8: =R8-Q8 -> -634 | Q8: =SUBTOTAL(9,$F$2:F8) -> 1902 | R8: =SUBTOTAL(9,$G$2:G8) -> 1268
A9: 05 | B9: 42919 | C9: Plumber | F9: 700 | I9: 5000093 | J9: y | K9: דוד סטורי | L9: 328 | N9: Y | P9: =R9-Q9 -> -1334 | Q9: =SUBTOTAL(9,$F$2:F9) -> 2602 | R9: =SUBTOTAL(9,$G$2:G9) -> 1268
A10: 05 | B10: 42934 | C10: gas installation | F10: 240 | I10: cc | J10: y | K10: electonic pro | L10: 1031624 | N10: Y | P10: =R10-Q10 -> -1574 | Q10: =SUBTOTAL(9,$F$2:F10) -> 2842 | R10: =SUBTOTAL(9,$G$2:G10) -> 1268
A11: 05 | B11: 42934 | C11: burners | F11: 1320 | I11: cc | J11: y | K11: Pr | L11: ov17501001177 | N11: Y | P11: =R11-Q11 -> -2894 | Q11: =SUBTOTAL(9,$F$2:F11) -> 4162 | R11: =SUBTOTAL(9,$G$2:G11) -> 1268
A12: 05 | B12: 42949 | C12: netvision 27-3-17 to 9-04-17 | F12: 163 | I12: cc | J12: y | K12: netvision | L12: 87572 | N12: Y | P12: =R12-Q12 -> -3057 | Q12: =SUBTOTAL(9,$F$2:F12) -> 4325 | R12: =SUBTOTAL(9,$G$2:G12) -> 1268
A13: 05 | B13: 42949 | C13: gas installation | F13: 200 | I13: 5000097 | J13: y | K13: david sheruti mizug | L13: 157 | N13: Y | P13: =R13-Q13 -> -3257 | Q13: =SUBTOTAL(9,$F$2:F13) -> 4525 | R13: =SUBTOTAL(9,$G$2:G13) -> 1268
A14: 05 | B14: 42962 | C14: ben cleaning | F14: 60 | J14: y | K14: ben | L14: no | N14: Y | P14: =R14-Q14 -> -3317 | Q14: =SUBTOTAL(9,$F$2:F14) -> 4585 | R14: =SUBTOTAL(9,$G$2:G14) -> 1268
A15: 05 | B15: 42996 | C15: prepaid expenses | G15: 3000 | J15: y | K15: mip | L15: 112 | N15: Y | P15: =R15-Q15 -> -317 | Q15: =SUBTOTAL(9,$F$2:F15) -> 4585 | R15: =SUBTOTAL(9,$G$2:G15) -> 4268
A16: 05 | B16: 43007 | C16: prepaid expenses | G16: 3032 | J16: y | K16: Mip | L16: 118 | N16: Y | P16: =R16-Q16 -> 2715 | Q16: =SUBTOTAL(9,$F$2:F16) -> 4585 | R16: =SUBTOTAL(9,$G$2:G16) -> 7300
A17: 05 | B17: 43023 | C17: Cleaning supplies | F17: 109.3 | I17: cc | J17: y | K17: Hendler | L17: 89010009 | N17: Y | P17: =R17-Q17 -> 2605.7 | Q17: =SUBTOTAL(9,$F$2:F17) -> 4694.3 | R17: =SUBTOTAL(9,$G$2:G17) -> 7300
A18: 05 | B18: 43025 | C18: water | F18: 11.9 | I18: cc | J18: y | K18: Mega bair | L18: 29600405012661 | N18: Y | P18: =R18-Q18 -> 2593.8 | Q18: =SUBTOTAL(9,$F$2:F18) -> 4706.2 | R18: =SUBTOTAL(9,$G$2:G18) -> 7300
A19: 05 | B19: 43025 | C19: groceries | F19: 119.82 | I19: cc | J19: y | K19: Hendler | L19: 9101009 | N19: Y | P19: =R19-Q19 -> 2473.98 | Q19: =SUBTOTAL(9,$F$2:F19) -> 4826.02 | R19: =SUBTOTAL(9,$G$2:G19) -> 7300
A20: 05 | B20: 43033 | C20: elecric | F20: 800 | I20: transfer | J20: y | K20: avv | L20: 254 | N20: Y | P20: =R20-Q20 -> 1673.98 | Q20: =SUBTOTAL(9,$F$2:F20) -> 5626.02 | R20: =SUBTOTAL(9,$G$2:G20) -> 7300
A21: 05 | B21: 43037 | C21: new key | F21: 12 | I21: cc | J21: y | K21: chaim manulim | L21: 8179 | N21: Y | P21: =R21-Q21 -> 1661.98 | Q21: =SUBTOTAL(9,$F$2:F21) -> 5638.02 | R21: =SUBTOTAL(9,$G$2:G21) -> 7300
A22: 05 | B22: 43039 | C22: water may June | F22: 134.5 | I22: cc | J22: y | K22: Tagid | L22: 5342 | N22: Y | P22: =R22-Q22 -> 1527.48 | Q22: =SUBTOTAL(9,$F$2:F22) -> 5772.52 | R22: =SUBTOTAL(9,$G$2:G22) -> 7300
A23: 05 | B23: 43039 | C23: water July August | F23: 426.7 | I23: cc | J23: y | K23: Tagit | L23: 5343 | N23: Y | P23: =R23-Q23 -> 1100.78 | Q23: =SUBTOTAL(9,$F$2:F23) -> 6199.22 | R23: =SUBTOTAL(9,$G$2:G23) -> 7300
A24: 05 | B24: 43039 | C24: electic June July | F24: 476.54 | I24: cc | J24: y | K24: electric | L24: 87395 | N24: Y | P24: =R24-Q24 -> 624.24 | Q24: =SUBTOTAL(9,$F$2:F24) -> 6675.76 | R24: =SUBTOTAL(9,$G$2:G24) -> 7300
A25: 05 | B25: 43040 | C25: cleaning BL | F25: 43.5 | J25: y | N25: Y | P25: =R25-Q25 -> 580.74 | Q25: =SUBTOTAL(9,$F$2:F25) -> 6719.26 | R25: =SUBTOTAL(9,$G$2:G25) -> 7300
A26: 05 | B26: 43040 | C26: cleaning 15/10 and 31/10 | F26: 615 | I26: transfer | J26: y | K26: elena | N26: Y | P26: =R26-Q26 -> -34.26 | Q26: =SUBTOTAL(9,$F$2:F26) -> 7334.26 | R26: =SUBTOTAL(9,$G$2:G26) -> 7300
A27: 05 | B27: 43055 | C27: cleaning | F27: 220 | I27: transfer | J27: y | K27: elena | N27: Y | P27: =R27-Q27 -> -254.26 | Q27: =SUBTOTAL(9,$F$2:F27) -> 7554.26 | R27: =SUBTOTAL(9,$G$2:G27) -> 7300
A28: 05 | B28: 43059 | C28: return of burner | G28: 600 | I28: 5008254 | J28: y | K28: pr | N28: Y | P28: =R28-Q28 -> 345.74 | Q28: =SUBTOTAL(9,$F$2:F28) -> 7554.26 | R28: =SUBTOTAL(9,$G$2:G28) -> 7900
A29: 05 | B29: 43060 | C29: Handyman | F29: 300 | I29: transfer | J29: y | K29: shalom shevach | L29: 327 | N29: Y | P29: =R29-Q29 -> 45.74 | Q29: =SUBTOTAL(9,$F$2:F29) -> 7854.26 | R29: =SUBTOTAL(9,$G$2:G29) -> 7900
A30: 05 | B30: 43061 | C30: elecrric box | H30: 2500 | I30: transfer | J30: y | K30: avi kodesh | N30: Y | P30: =R30-Q30 -> 45.74 | Q30: =SUBTOTAL(9,$F$2:F30) -> 7854.26 | R30: =SUBTOTAL(9,$G$2:G30) -> 7900
A31: 05 | B31: 43110 | C31: electric august to Dec | F31: 920.75 | I31: cc | J31: y | N31: Y | P31: =R31-Q31 -> -875.01 | Q31: =SUBTOTAL(9,$F$2:F31) -> 8775.01 | R31: =SUBTOTAL(9,$G$2:G31) -> 7900
A32: 05 | B32: 43115 | C32: water August - December | H32: 1289.6 | J32: y | N32: Y | P32: =R32-Q32 -> -875.01 | Q32: =SUBTOTAL(9,$F$2:F32) -> 8775.01 | R32: =SUBTOTAL(9,$G$2:G32) -> 7900
A33: 05 | B33: 43117 | C33: toilet and leak | F33: 877 | I33: 5000121 | J33: y | K33: Erez Lvenberg | L33: 8146 | N33: Y | P33: =R33-Q33 -> -1752.01 | Q33: =SUBTOTAL(9,$F$2:F33) -> 9652.01 | R33: =SUBTOTAL(9,$G$2:G33) -> 7900
A34: 05 | B34: 43120 | C34: fridge technicain | F34: 150 | I34: 5000122 | J34: y | K34: Aronav Alex | L34: 9848 | N34: Y | P34: =R34-Q34 -> -1902.01 | Q34: =SUBTOTAL(9,$F$2:F34) -> 9802.01 | R34: =SUBTOTAL(9,$G$2:G34) -> 7900
A35: 05 | B35: 43123 | C35: prepaid expenses | G35: 1000 | J35: y | L35: 146 | N35: Y | P35: =R35-Q35 -> -902.01 | Q35: =SUBTOTAL(9,$F$2:F35) -> 9802.01 | R35: =SUBTOTAL(9,$G$2:G35) -> 8900
A36: 05 | B36: 43130 | C36: faucet | F36: 596 | I36: cc | J36: y | K36: Ronis | L36: RC189000105 | N36: Y | P36: =R36-Q36 -> -1498.01 | Q36: =SUBTOTAL(9,$F$2:F36) -> 10398.01 | R36: =SUBTOTAL(9,$G$2:G36) -> 8900
A37: 05 | B37: 43130 | C37: electiric water - Hannah | G37: 2016 | I37: deposit | J37: y | L37: 144 | N37: Y | P37: =R37-Q37 -> 517.99 | Q37: =SUBTOTAL(9,$F$2:F37) -> 10398.01 | R37: =SUBTOTAL(9,$G$2:G37) -> 10916
A38: 05 | B38: 43130 | C38: electric water tamar | G38: 520 | I38: deposit | J38: y | L38: 141 | N38: Y | P38: =R38-Q38 -> 1037.99 | Q38: =SUBTOTAL(9,$F$2:F38) -> 10398.01 | R38: =SUBTOTAL(9,$G$2:G38) -> 11436
A39: 05 | B39: 43131 | C39: electric water tamar | G39: 15 | I39: from buffer | J39: y | N39: Y | P39: =R39-Q39 -> 1052.99 | Q39: =SUBTOTAL(9,$F$2:F39) -> 10398.01 | R39: =SUBTOTAL(9,$G$2:G39) -> 11451
A40: 05 | B40: 43132 | C40: faucet /toliet | F40: 645 | I40: 5000124 | J40: y | K40: tim | N40: Y | P40: =R40-Q40 -> 407.99 | Q40: =SUBTOTAL(9,$F$2:F40) -> 11043.01 | R40: =SUBTOTAL(9,$G$2:G40) -> 11451
...

Sheet c4 EX
A1: Prop ID | B1: Date | C1: Section | D1: Notes | E1: Type | F1: Amount | G1: Inflow | H1: He/She paid | I1: Method | J1: Reconciled | K1: Company | L1: Reciept | M1: Rental income | N1: Reported | O1: Report sent | P1: Balance | Q1: Total Amount | R1: Total Inflow
A2: C4 | B2: 44131 | C2: נייר טואלט | F2: 99.6 | I2: cc | J2: y | K2: הנדלר | L2: 971 | N2: Y | P2: =R2-Q2 -> -99.6 | Q2: =SUBTOTAL(9,$F$2:F2) -> 99.6 | R2: =SUBTOTAL(9,$G$2:G2) -> 0
A3: C4 | B3: 44132 | C3: Pre paid | G3: 3600 | N3: Y | P3: =R3-Q3 -> 3500.4 | Q3: =SUBTOTAL(9,$F$2:F3) -> 99.6 | R3: =SUBTOTAL(9,$G$2:G3) -> 3600
A4: C4 | B4: 44139 | C4: מחסנית סיליפוס | F4: 370 | I4: cc | J4: y | K4: עמיעד | L4: 8131 | N4: Y | P4: =R4-Q4 -> 3130.4 | Q4: =SUBTOTAL(9,$F$2:F4) -> 469.6 | R4: =SUBTOTAL(9,$G$2:G4) -> 3600
A5: C4 | B5: 44144 | C5: גינון | F5: 2400 | I5: מזומן | J5: y | N5: Y | P5: =R5-Q5 -> 730.4 | Q5: =SUBTOTAL(9,$F$2:F5) -> 2869.6 | R5: =SUBTOTAL(9,$G$2:G5) -> 3600
A6: C4 | B6: 44172 | C6: גינון | F6: 2200 | I6: מזומן | J6: y | N6: Y | P6: =R6-Q6 -> -1469.6 | Q6: =SUBTOTAL(9,$F$2:F6) -> 5069.6 | R6: =SUBTOTAL(9,$G$2:G6) -> 3600
A7: C4 | B7: 44173 | C7: Cleaning november | F7: 535.78 | I7: t | J7: y | N7: Y | P7: =R7-Q7 -> -2005.38 | Q7: =SUBTOTAL(9,$F$2:F7) -> 5605.38 | R7: =SUBTOTAL(9,$G$2:G7) -> 3600
A8: C4 | B8: 44173 | C8: pensia Cleaning november | F8: 105.52 | I8: t | J8: y | N8: Y | P8: =R8-Q8 -> -2110.9 | Q8: =SUBTOTAL(9,$F$2:F8) -> 5710.9 | R8: =SUBTOTAL(9,$G$2:G8) -> 3600
A9: C4 | B9: 44173 | C9: תשלום | G9: 5000 | I9: t | J9: y | N9: Y | P9: =R9-Q9 -> 2889.1 | Q9: =SUBTOTAL(9,$F$2:F9) -> 5710.9 | R9: =SUBTOTAL(9,$G$2:G9) -> 8600
A10: C4 | B10: 44185 | C10: Bituach Leumi cleaner Nov | F10: 42.78 | I10: t | J10: y | N10: Y | P10: =R10-Q10 -> 2846.32 | Q10: =SUBTOTAL(9,$F$2:F10) -> 5753.68 | R10: =SUBTOTAL(9,$G$2:G10) -> 8600
A11: C4 | B11: 44200 | C11: גנן ותיקון מכונת כביסה | F11: 1300 | I11: cash | J11: y | N11: Y | P11: =R11-Q11 -> 1546.32 | Q11: =SUBTOTAL(9,$F$2:F11) -> 7053.68 | R11: =SUBTOTAL(9,$G$2:G11) -> 8600
A12: C4 | B12: 44203 | C12: Cleaning dec | F12: 1161.96 | I12: t | J12: y | N12: Y | P12: =R12-Q12 -> 384.36 | Q12: =SUBTOTAL(9,$F$2:F12) -> 8215.64 | R12: =SUBTOTAL(9,$G$2:G12) -> 8600
A13: C4 | B13: 44203 | C13: pensia Cleaning dec | F13: 225.12 | I13: t | J13: y | N13: Y | P13: =R13-Q13 -> 159.24 | Q13: =SUBTOTAL(9,$F$2:F13) -> 8440.76 | R13: =SUBTOTAL(9,$G$2:G13) -> 8600
A14: C4 | B14: 44216 | C14: Bituach Leumi cleaner Dec | F14: 93.4 | I14: t | J14: y | N14: Y | P14: =R14-Q14 -> 65.84 | Q14: =SUBTOTAL(9,$F$2:F14) -> 8534.16 | R14: =SUBTOTAL(9,$G$2:G14) -> 8600
A15: C4 | B15: 44228 | C15: מתלה לקיר | F15: 29.9 | I15: cc | J15: y | K15: סופר דיל | L15: 230 | N15: Y | P15: =R15-Q15 -> 35.94 | Q15: =SUBTOTAL(9,$F$2:F15) -> 8564.06 | R15: =SUBTOTAL(9,$G$2:G15) -> 8600
A16: C4 | B16: 44232 | C16: Advance | G16: 6000 | I16: t | J16: y | N16: Y | P16: =R16-Q16 -> 6035.94 | Q16: =SUBTOTAL(9,$F$2:F16) -> 8564.06 | R16: =SUBTOTAL(9,$G$2:G16) -> 14600
A17: C4 | B17: 44234 | C17: Cleaning jan | F17: 395.08 | I17: t | J17: y | N17: Y | P17: =R17-Q17 -> 5640.86 | Q17: =SUBTOTAL(9,$F$2:F17) -> 8959.14 | R17: =SUBTOTAL(9,$G$2:G17) -> 14600
A18: C4 | B18: 44234 | C18: pensia Cleaning jan | F18: 76.72 | I18: t | J18: y | N18: Y | P18: =R18-Q18 -> 5564.14 | Q18: =SUBTOTAL(9,$F$2:F18) -> 9035.86 | R18: =SUBTOTAL(9,$G$2:G18) -> 14600
A19: C4 | B19: 44236 | C19: גינון | F19: 1800 | I19: cash | J19: y | N19: Y | P19: =R19-Q19 -> 3764.14 | Q19: =SUBTOTAL(9,$F$2:F19) -> 10835.86 | R19: =SUBTOTAL(9,$G$2:G19) -> 14600
A20: C4 | B20: 44246 | C20: חומרי ניקיון | F20: 227.5 | I20: באפר | K20: שופרסל | L20: 9569 | N20: Y | P20: =R20-Q20 -> 3536.64 | Q20: =SUBTOTAL(9,$F$2:F20) -> 11063.36 | R20: =SUBTOTAL(9,$G$2:G20) -> 14600
A21: C4 | B21: 44247 | C21: Bituach Leumi cleaner Jan | F21: 31.34 | I21: t | J21: y | N21: Y | P21: =R21-Q21 -> 3505.3 | Q21: =SUBTOTAL(9,$F$2:F21) -> 11094.7 | R21: =SUBTOTAL(9,$G$2:G21) -> 14600
A22: C4 | B22: 44256 | C22: גינון | F22: 1200 | I22: cash | J22: y | N22: Y | P22: =R22-Q22 -> 2305.3 | Q22: =SUBTOTAL(9,$F$2:F22) -> 12294.7 | R22: =SUBTOTAL(9,$G$2:G22) -> 14600
A23: C4 | B23: 44259 | C23: Cleaning March | F23: 950.96 | N23: Y | P23: =R23-Q23 -> 1354.34 | Q23: =SUBTOTAL(9,$F$2:F23) -> 13245.66 | R23: =SUBTOTAL(9,$G$2:G23) -> 14600
A24: C4 | B24: 44259 | C24: pensia Cleaning March | F24: 182.15 | N24: Y | P24: =R24-Q24 -> 1172.19 | Q24: =SUBTOTAL(9,$F$2:F24) -> 13427.81 | R24: =SUBTOTAL(9,$G$2:G24) -> 14600
A25: C4 | B25: 44264 | C25: בדיקת מכונת כביסה | F25: 350 | I25: t | J25: y | K25: ירון דריקס | L25: 5410 | N25: Y | P25: =R25-Q25 -> 822.19 | Q25: =SUBTOTAL(9,$F$2:F25) -> 13777.81 | R25: =SUBTOTAL(9,$G$2:G25) -> 14600
A26: C4 | B26: 44267 | C26: תנור אמבטיה | F26: 89 | K26: טלראן | N26: Y | P26: =R26-Q26 -> 733.19 | Q26: =SUBTOTAL(9,$F$2:F26) -> 13866.81 | R26: =SUBTOTAL(9,$G$2:G26) -> 14600
A27: C4 | B27: 44271 | C27: החלפת טרמוסטט וגוף חימום | F27: 1228 | I27: t | J27: y | K27: עוז אגסי | L27: 4317 | N27: Y | P27: =R27-Q27 -> -494.81 | Q27: =SUBTOTAL(9,$F$2:F27) -> 15094.81 | R27: =SUBTOTAL(9,$G$2:G27) -> 14600
A28: C4 | B28: 44271 | C28: תיקון תריס חשמלי | F28: 527 | I28: t | J28: y | K28: צביקה | L28: 50118 | N28: Y | P28: =R28-Q28 -> -1021.81 | Q28: =SUBTOTAL(9,$F$2:F28) -> 15621.81 | R28: =SUBTOTAL(9,$G$2:G28) -> 14600
A29: C4 | B29: 44272 | C29: סופר דיל | F29: 19.9 | I29: cc | J29: y | N29: Y | P29: =R29-Q29 -> -1041.71 | Q29: =SUBTOTAL(9,$F$2:F29) -> 15641.71 | R29: =SUBTOTAL(9,$G$2:G29) -> 14600
A30: C4 | B30: 44275 | C30: Bituach Leumi cleaner March | F30: 74.74 | N30: Y | P30: =R30-Q30 -> -1116.45 | Q30: =SUBTOTAL(9,$F$2:F30) -> 15716.45 | R30: =SUBTOTAL(9,$G$2:G30) -> 14600
A31: C4 | B31: 44293 | C31: Cleaning mer | F31: 1228 | I31: t | J31: y | N31: Y | P31: =R31-Q31 -> -2344.45 | Q31: =SUBTOTAL(9,$F$2:F31) -> 16944.45 | R31: =SUBTOTAL(9,$G$2:G31) -> 14600
A32: C4 | B32: 44297 | C32: Advance | G32: 12000 | I32: t | J32: y | N32: Y | P32: =R32-Q32 -> 9655.55 | Q32: =SUBTOTAL(9,$F$2:F32) -> 16944.45 | R32: =SUBTOTAL(9,$G$2:G32) -> 26600
A33: C4 | B33: 44298 | C33: pensia Cleaning mer | F33: 252.95 | I33: t | J33: y | N33: Y | P33: =R33-Q33 -> 9402.6 | Q33: =SUBTOTAL(9,$F$2:F33) -> 17197.4 | R33: =SUBTOTAL(9,$G$2:G33) -> 26600
A34: C4 | B34: 44298 | C34: גינון | F34: 6000 | I34: cash | J34: y | N34: Y | P34: =R34-Q34 -> 3402.6 | Q34: =SUBTOTAL(9,$F$2:F34) -> 23197.4 | R34: =SUBTOTAL(9,$G$2:G34) -> 26600
A35: C4 | B35: 44306 | C35: Bituach Leumi cleaner Mar | F35: 141.89 | I35: t | J35: y | N35: Y | P35: =R35-Q35 -> 3260.71 | Q35: =SUBTOTAL(9,$F$2:F35) -> 23339.29 | R35: =SUBTOTAL(9,$G$2:G35) -> 26600
A36: C4 | B36: 44318 | C36: איזולירבנד | F36: 49 | I36: cc | J36: y | K36: בנדק | N36: Y | P36: =R36-Q36 -> 3211.71 | Q36: =SUBTOTAL(9,$F$2:F36) -> 23388.29 | R36: =SUBTOTAL(9,$G$2:G36) -> 26600
A37: C4 | B37: 44322 | C37: Cleaning april | F37: 1255.64 | N37: Y | P37: =R37-Q37 -> 1956.07 | Q37: =SUBTOTAL(9,$F$2:F37) -> 24643.93 | R37: =SUBTOTAL(9,$G$2:G37) -> 26600
A38: C4 | B38: 44322 | C38: pensia Cleaning april | F38: 244.64 | N38: Y | P38: =R38-Q38 -> 1711.43 | Q38: =SUBTOTAL(9,$F$2:F38) -> 24888.57 | R38: =SUBTOTAL(9,$G$2:G38) -> 26600
A39: C4 | B39: 44325 | C39: גינון | F39: 6000 | I39: cash | J39: ט | N39: Y | P39: =R39-Q39 -> -4288.57 | Q39: =SUBTOTAL(9,$F$2:F39) -> 30888.57 | R39: =SUBTOTAL(9,$G$2:G39) -> 26600
A40: C4 | B40: 44326 | C40: פילטר | F40: 530 | I40: cc | K40: מנדלסון | L40: 2712 | N40: Y | P40: =R40-Q40 -> -4818.57 | Q40: =SUBTOTAL(9,$F$2:F40) -> 31418.57 | R40: =SUBTOTAL(9,$G$2:G40) -> 26600
...

Sheet 06
A1: Type | B1: Coment | C1: Name | D1: Company | E1: contract # | F1: Phone | G1: email | H1: customer # | I1: Meter # | J1: Payment method | L1: # Kriya | M1: wrranty | P1: model | Q1: serial #
A2: Personal | B2: Naomi and Eli Wurtman | E2: kfar Etzion 19 Jerusalem
A3: Personal | B3: Naomi | C3: 544872318
A4: Personal | B4: Eli
A8: contractor | B8: door | C8: Sagit | D8: next door | F8: 722400466 | G8: 054-5333956- yicel
A9: contractor | B9: kablan | C9: Ashraf | F9: 050-5566667
A10: contractor | B10: kablan | C10: Nassim | F10: 052-3718800
A11: contractor | B11: gardener | C11: Itamar | F11: 050-5517687
A12: appliance | B12: surge protector | D12: sherut mazor | F12: 04-6773000 | M12: 3 year warranty | O12: 42977 | P12: W85F44P/I
A13: appliance | B13: washing machine | D13: Gorenje | F13: 04-677300o

Sheet 09 ex
A1: Prop ID | B1: Date | C1: Section | D1: Notes | E1: Type | F1: Amount | G1: Inflow | H1: He/She paid | I1: Method | J1: Reconciled | K1: Company | L1: Reciept | M1: Rental income | N1: Reported | O1: Report sent | P1: Balance | Q1: Total Amount | R1: Total Inflow
A2: 09 | B2: 43671 | C2: Pre paid | G2: 1000 | I2: שק | J2: y | P2: =R2-Q2 -> 1000 | Q2: =SUBTOTAL(9,$F$2:F2) -> 0 | R2: =SUBTOTAL(9,$G$2:G2) -> 1000
A3: 09 | B3: 43724 | C3: Cleaning supplies | F3: 125.79 | I3: cc | J3: y | K3: הנדלר | L3: 11 | P3: =R3-Q3 -> 874.21 | Q3: =SUBTOTAL(9,$F$2:F3) -> 125.79 | R3: =SUBTOTAL(9,$G$2:G3) -> 1000
A4: 09 | B4: 43741 | C4: Cleaning September 2019 | F4: 113.79 | I4: t | J4: t | P4: =R4-Q4 -> 760.42 | Q4: =SUBTOTAL(9,$F$2:F4) -> 239.58 | R4: =SUBTOTAL(9,$G$2:G4) -> 1000
A5: 09 | B5: 43744 | C5: Pensia cleaning September 2019 | F5: 19.15 | I5: t | J5: y | P5: =R5-Q5 -> 741.27 | Q5: =SUBTOTAL(9,$F$2:F5) -> 258.73 | R5: =SUBTOTAL(9,$G$2:G5) -> 1000
A6: 09 | B6: 43758 | C6: Bituach Leumi cleaning September 2019 | F6: 7.8 | I6: t | J6: y | P6: =R6-Q6 -> 733.47 | Q6: =SUBTOTAL(9,$F$2:F6) -> 266.53 | R6: =SUBTOTAL(9,$G$2:G6) -> 1000
A7: 09 | B7: 43850 | C7: Food | F7: 35.24 | I7: cc | J7: y | P7: =R7-Q7 -> 698.23 | Q7: =SUBTOTAL(9,$F$2:F7) -> 301.77 | R7: =SUBTOTAL(9,$G$2:G7) -> 1000
A8: 09 | B8: 43867 | C8: Cleaning June 2020 | D8: Elena | F8: 207.54 | I8: t | J8: y | P8: =R8-Q8 -> 490.69 | Q8: =SUBTOTAL(9,$F$2:F8) -> 509.31 | R8: =SUBTOTAL(9,$G$2:G8) -> 1000
A9: 09 | B9: 43867 | C9: Pension cleaning June 2020 | D9: Elena | F9: 38.38 | I9: t | J9: y | P9: =R9-Q9 -> 452.31 | Q9: =SUBTOTAL(9,$F$2:F9) -> 547.69 | R9: =SUBTOTAL(9,$G$2:G9) -> 1000
A10: 09 | B10: 43870 | C10: Electrician | F10: 200 | I10: t | J10: y | K10: אבי קודיש | P10: =R10-Q10 -> 252.31 | Q10: =SUBTOTAL(9,$F$2:F10) -> 747.69 | R10: =SUBTOTAL(9,$G$2:G10) -> 1000
A11: 09 | B11: 43881 | C11: Bituach Leumi cleaning June 2020 | D11: Elena | F11: 15.71 | I11: t | J11: y | P11: =R11-Q11 -> 236.6 | Q11: =SUBTOTAL(9,$F$2:F11) -> 763.4 | R11: =SUBTOTAL(9,$G$2:G11) -> 1000
A12: 09 | B12: 44259 | C12: Cleaning Marchruary 2020 | D12: Elena | F12: 160.68 | I12: t | J12: y | P12: =R12-Q12 -> 75.92 | Q12: =SUBTOTAL(9,$F$2:F12) -> 924.08 | R12: =SUBTOTAL(9,$G$2:G12) -> 1000
A13: 09 | B13: 44275 | C13: Bituach Leumi cleaning Marchruary 2021 | D13: Elena | F13: 11.8 | I13: t | J13: y | P13: =R13-Q13 -> 64.12 | Q13: =SUBTOTAL(9,$F$2:F13) -> 935.88 | R13: =SUBTOTAL(9,$G$2:G13) -> 1000
A14: 09 | B14: 44298 | C14: Pension cleaning Marchruary 2021 | D14: Elena | F14: 28.76 | I14: t | J14: y | P14: =R14-Q14 -> 35.36 | Q14: =SUBTOTAL(9,$F$2:F14) -> 964.64 | R14: =SUBTOTAL(9,$G$2:G14) -> 1000
A15: 09 | B15: 44419 | C15: Cleaning July 2021 | D15: Elena | F15: 528.65 | P15: =R15-Q15 -> -493.29 | Q15: =SUBTOTAL(9,$F$2:F15) -> 1493.29 | R15: =SUBTOTAL(9,$G$2:G15) -> 1000
A16: 09 | B16: 44420 | C16: Pension cleaning July 2021 | D16: Elena | F16: 96.65 | P16: =R16-Q16 -> -589.94 | Q16: =SUBTOTAL(9,$F$2:F16) -> 1589.94 | R16: =SUBTOTAL(9,$G$2:G16) -> 1000
A17: 09 | B17: 44428 | C17: Bituach Leumi cleaning July 2021 | D17: Elena | F17: 45.8 | P17: =R17-Q17 -> -635.74 | Q17: =SUBTOTAL(9,$F$2:F17) -> 1635.74 | R17: =SUBTOTAL(9,$G$2:G17) -> 1000
A18: 09 | B18: 44456 | C18: Filter replacement | F18: 585 | K18: אשר ברינבאום | L18: 975 | P18: =R18-Q18 -> -1220.74 | Q18: =SUBTOTAL(9,$F$2:F18) -> 2220.74 | R18: =SUBTOTAL(9,$G$2:G18) -> 1000
A19: 09 | B19: 44468 | C19: Water bill | F19: 32.6 | I19: cc | J19: y | P19: =R19-Q19 -> -1253.34 | Q19: =SUBTOTAL(9,$F$2:F19) -> 2253.34 | R19: =SUBTOTAL(9,$G$2:G19) -> 1000
A20: 09 | B20: 44563 | C20: סגירת חשבון | G20: 1253.34

Sheet 06 ex
A1: Prop ID | B1: Date | C1: Section | D1: Notes | E1: Type | F1: Amount | G1: Inflow | H1: He/She paid | I1: Method | J1: Reconciled | K1: Company | L1: Reciept | M1: Rental income | N1: Reported | O1: Report sent | P1: Balance | Q1: Total Amount | R1: Total Inflow
A2: C6 | B2: 42936 | C2: prepaid | G2: 2000 | I2: transfer | J2: y | K2: MIP | L2: 95 | N2: Y | P2: =R2-Q2 -> 2000 | Q2: =SUBTOTAL(9,$F$2:F2) -> 0 | R2: =SUBTOTAL(9,$G$2:G2) -> 2000
A3: C6 | B3: 42941 | C3: toilet paper | F3: 34.9 | I3: cc | J3: y | K3: Bitan | L3: 163454 | N3: Y | P3: =R3-Q3 -> 1965.1 | Q3: =SUBTOTAL(9,$F$2:F3) -> 34.9 | R3: =SUBTOTAL(9,$G$2:G3) -> 2000
A4: C6 | B4: 42941 | C4: electtican | F4: 400 | I4: 5000094 | J4: y | K4: mesri | N4: Y | P4: =R4-Q4 -> 1565.1 | Q4: =SUBTOTAL(9,$F$2:F4) -> 434.9 | R4: =SUBTOTAL(9,$G$2:G4) -> 2000
A5: C6 | B5: 42946 | C5: cleaning | F5: 20 | J5: y | K5: ben | N5: Y | P5: =R5-Q5 -> 1545.1 | Q5: =SUBTOTAL(9,$F$2:F5) -> 454.9 | R5: =SUBTOTAL(9,$G$2:G5) -> 2000
A6: C6 | B6: 42947 | C6: exterminaor | F6: 700 | I6: transfer | J6: y | K6: Adi Hadbara | L6: 2492 | N6: Y | P6: =R6-Q6 -> 845.1 | Q6: =SUBTOTAL(9,$F$2:F6) -> 1154.9 | R6: =SUBTOTAL(9,$G$2:G6) -> 2000
A7: C6 | B7: 42950 | C7: tris repair | F7: 351 | I7: transfer | J7: y | K7: tzkia | L7: 40005 | N7: Y | P7: =R7-Q7 -> 494.1 | Q7: =SUBTOTAL(9,$F$2:F7) -> 1505.9 | R7: =SUBTOTAL(9,$G$2:G7) -> 2000
A8: C6 | B8: 42956 | C8: electrican | H8: 5000 | J8: y | K8: avi kosesh | L8: 223 | N8: Y | P8: =R8-Q8 -> 494.1 | Q8: =SUBTOTAL(9,$F$2:F8) -> 1505.9 | R8: =SUBTOTAL(9,$G$2:G8) -> 2000
A9: C6 | B9: 42977 | C9: surge protercor | F9: 480 | I9: cc | J9: y | K9: Sherut Mazaon | L9: 271047 | N9: Y | P9: =R9-Q9 -> 14.1 | Q9: =SUBTOTAL(9,$F$2:F9) -> 1985.9 | R9: =SUBTOTAL(9,$G$2:G9) -> 2000
A10: C6 | B10: 42989 | C10: ipardox app | F10: 71 | J10: y | K10: google play | L10: 3361-9825-2 | N10: Y | P10: =R10-Q10 -> -56.9 | Q10: =SUBTOTAL(9,$F$2:F10) -> 2056.9 | R10: =SUBTOTAL(9,$G$2:G10) -> 2000
A11: C6 | B11: 42990 | C11: prepaid | G11: 5000 | J11: y | K11: mip | L11: 108 | N11: Y | P11: =R11-Q11 -> 4943.1 | Q11: =SUBTOTAL(9,$F$2:F11) -> 2056.9 | R11: =SUBTOTAL(9,$G$2:G11) -> 7000
A12: C6 | B12: 42997 | C12: bird prevention | F12: 900 | I12: transfer | J12: y | K12: Danziman | L12: 50016 | N12: Y | P12: =R12-Q12 -> 4043.1 | Q12: =SUBTOTAL(9,$F$2:F12) -> 2956.9 | R12: =SUBTOTAL(9,$G$2:G12) -> 7000
A13: C6 | B13: 42997 | C13: a/c | F13: 960 | I13: transfer | J13: y | K13: mizug habaron | N13: Y | P13: =R13-Q13 -> 3083.1 | Q13: =SUBTOTAL(9,$F$2:F13) -> 3916.9 | R13: =SUBTOTAL(9,$G$2:G13) -> 7000
A14: C6 | B14: 43009 | C14: cleaning | F14: 250 | I14: cash | J14: y | K14: manny | N14: Y | P14: =R14-Q14 -> 2833.1 | Q14: =SUBTOTAL(9,$F$2:F14) -> 4166.9 | R14: =SUBTOTAL(9,$G$2:G14) -> 7000
